[2024-02-29T22:49:08.603+0000] {taskinstance.py:1979} INFO - Dependencies all met for dep_context=non-requeueable deps ti=<TaskInstance: our_dag_with_python_operator_v04.greet scheduled__2024-02-28T00:00:00+00:00 [queued]>
[2024-02-29T22:49:08.609+0000] {taskinstance.py:1979} INFO - Dependencies all met for dep_context=requeueable deps ti=<TaskInstance: our_dag_with_python_operator_v04.greet scheduled__2024-02-28T00:00:00+00:00 [queued]>
[2024-02-29T22:49:08.609+0000] {taskinstance.py:2193} INFO - Starting attempt 1 of 6
[2024-02-29T22:49:08.615+0000] {taskinstance.py:2214} INFO - Executing <Task(PythonOperator): greet> on 2024-02-28 00:00:00+00:00
[2024-02-29T22:49:08.619+0000] {standard_task_runner.py:60} INFO - Started process 4600 to run task
[2024-02-29T22:49:08.622+0000] {standard_task_runner.py:87} INFO - Running: ['***', 'tasks', 'run', 'our_dag_with_python_operator_v04', 'greet', 'scheduled__2024-02-28T00:00:00+00:00', '--job-id', '14', '--raw', '--subdir', 'DAGS_FOLDER/create_dag_with_python_operator.py', '--cfg-path', '/tmp/tmpohgnh38w']
[2024-02-29T22:49:08.624+0000] {standard_task_runner.py:88} INFO - Job 14: Subtask greet
[2024-02-29T22:49:08.659+0000] {task_command.py:423} INFO - Running <TaskInstance: our_dag_with_python_operator_v04.greet scheduled__2024-02-28T00:00:00+00:00 [running]> on host 417e643aed36
[2024-02-29T22:49:08.796+0000] {taskinstance.py:2510} INFO - Exporting env vars: AIRFLOW_CTX_DAG_OWNER='dn' AIRFLOW_CTX_DAG_ID='our_dag_with_python_operator_v04' AIRFLOW_CTX_TASK_ID='greet' AIRFLOW_CTX_EXECUTION_DATE='2024-02-28T00:00:00+00:00' AIRFLOW_CTX_TRY_NUMBER='1' AIRFLOW_CTX_DAG_RUN_ID='scheduled__2024-02-28T00:00:00+00:00'
[2024-02-29T22:49:08.797+0000] {taskinstance.py:2728} ERROR - Task failed with exception
Traceback (most recent call last):
  File "/home/airflow/.local/lib/python3.11/site-packages/airflow/models/taskinstance.py", line 444, in _execute_task
    result = _execute_callable(context=context, **execute_callable_kwargs)
             ^^^^^^^^^^^^^^^^^^^^^^^^^^^^^^^^^^^^^^^^^^^^^^^^^^^^^^^^^^^^^
  File "/home/airflow/.local/lib/python3.11/site-packages/airflow/models/taskinstance.py", line 414, in _execute_callable
    return execute_callable(context=context, **execute_callable_kwargs)
           ^^^^^^^^^^^^^^^^^^^^^^^^^^^^^^^^^^^^^^^^^^^^^^^^^^^^^^^^^^^^
  File "/home/airflow/.local/lib/python3.11/site-packages/airflow/operators/python.py", line 200, in execute
    return_value = self.execute_callable()
                   ^^^^^^^^^^^^^^^^^^^^^^^
  File "/home/airflow/.local/lib/python3.11/site-packages/airflow/operators/python.py", line 217, in execute_callable
    return self.python_callable(*self.op_args, **self.op_kwargs)
           ^^^^^^^^^^^^^^^^^^^^^^^^^^^^^^^^^^^^^^^^^^^^^^^^^^^^^
  File "/opt/airflow/dags/create_dag_with_python_operator.py", line 12, in greet
    name = ti.xcoms_pull(task_ids='get_name')
           ^^^^^^^^^^^^^
AttributeError: 'TaskInstance' object has no attribute 'xcoms_pull'
[2024-02-29T22:49:08.806+0000] {taskinstance.py:1149} INFO - Marking task as UP_FOR_RETRY. dag_id=our_dag_with_python_operator_v04, task_id=greet, execution_date=20240228T000000, start_date=20240229T224908, end_date=20240229T224908
[2024-02-29T22:49:08.812+0000] {standard_task_runner.py:107} ERROR - Failed to execute job 14 for task greet ('TaskInstance' object has no attribute 'xcoms_pull'; 4600)
[2024-02-29T22:49:08.841+0000] {local_task_job_runner.py:234} INFO - Task exited with return code 1
[2024-02-29T22:49:08.852+0000] {taskinstance.py:3309} INFO - 0 downstream tasks scheduled from follow-on schedule check
